<mujoco model="yahboom_dofbot">
  <compiler angle="radian" meshdir="meshes/"/>

  <asset>
    <texture type="skybox" builtin="gradient" rgb1="1 1 1" rgb2=".6 .8 1" width="256" height="256"/>
    <texture name="grid" type="2d" builtin="checker" width="512" height="512" rgb1="1 1 1" rgb2=".2 .3 .4"/>
    <material name="grid" texture="grid" texrepeat="1 1" texuniform="true" reflectance=".2"/>
    <mesh name="base_link" file="base_link.STL"/>
    <mesh name="arm_link1" file="arm_link1.STL"/>
    <mesh name="arm_link2" file="arm_link2.STL"/>
    <mesh name="arm_link3" file="arm_link3.STL"/>
    <mesh name="arm_link4" file="arm_link4.STL"/>
    <mesh name="arm_link5" file="arm_link5.STL"/>
    <mesh name="rlink1" file="rlink1.STL"/>
    <mesh name="rlink2" file="rlink2.STL"/>
    <mesh name="rlink3" file="rlink3.STL"/>
    <mesh name="llink1" file="llink1.STL"/>
    <mesh name="llink2" file="llink2.STL"/>
    <mesh name="llink3" file="llink3.STL"/>
  </asset>

  <worldbody>
	<body name="base_link">
    <geom type="mesh" contype="0" conaffinity="0" group="1" density="0" rgba="0.2 0.2 0.2 1" mesh="base_link"/>
    <geom type="mesh" rgba="0.2 0.2 0.2 1" mesh="base_link"/>
    <body name="arm_link1" pos="0 0 0.06605" quat="0.731678 -0.00395293 -0.00368254 0.681629">
      <inertial pos="1.9918e-05 -5.98355e-05 0.0114289" quat="0.503495 0.496992 -0.499932 0.499559" mass="0.0279545" diaginertia="1.49641e-05 1.19145e-05 1.0564e-05"/>
      <joint name="arm_joint1" pos="0 0 0" axis="0 0 1" range="-1.5708 1.5708" damping="0.1" type="hinge" />
      <geom type="mesh" contype="0" conaffinity="0" group="1" density="0" rgba="1 1 1 1" mesh="arm_link1"/>
      <geom type="mesh" rgba="1 1 1 1" mesh="arm_link1"/>
      <body name="arm_link2" pos="0 0 0.0405" quat="0.707105 -0.707108 0 0">
        <inertial pos="0.024903 -0.0022632 -0.00066663" quat="0.487261 0.491406 0.51243 0.508441" mass="0.031605" diaginertia="2.67072e-05 2.46962e-05 5.81105e-06"/>
        <joint name="arm_joint2" pos="0 0 0" axis="0 0 -1" range="-1.5708 1.5708" damping="0.1"/>
        <geom type="mesh" contype="0" conaffinity="0" group="1" density="0" rgba="1 1 1 1" mesh="arm_link2"/>
        <geom type="mesh" rgba="1 1 1 1" mesh="arm_link2"/>
        <body name="arm_link3" pos="0 -0.0829 0">
          <inertial pos="0.024903 -0.0022634 -0.0013962" quat="0.487109 0.491568 0.512017 0.508846" mass="0.031605" diaginertia="2.67072e-05 2.46961e-05 5.81093e-06"/>
          <joint name="arm_joint3" pos="0 0 0" axis="0 0 -1" range="-1.5708 1.5708" damping="0.1"/>
          <geom type="mesh" contype="0" conaffinity="0" group="1" density="0" rgba="1 1 1 1" mesh="arm_link3"/>
          <geom type="mesh" rgba="1 1 1 1" mesh="arm_link3"/>
          <body name="arm_link4" pos="0 -0.0829 0">
            <inertial pos="0.036246 0.0023413 -0.0019655" quat="-0.0965524 0.702171 0.0765377 0.701267" mass="0.049766" diaginertia="4.17722e-05 3.79571e-05 1.02197e-05"/>
            <joint name="arm_joint4" pos="0 0 0" axis="0 0 -1" range="-1.5708 1.5708" damping="0.1"/>
            <geom type="mesh" contype="0" conaffinity="0" group="1" density="0" rgba="1 1 1 1" mesh="arm_link4"/>
            <geom type="mesh" rgba="1 1 1 1" mesh="arm_link4"/>
            <body name="arm_link5" pos="-0.00215 -0.17455 0" quat="0.707105 0.707108 0 0">
              <inertial pos="0.0023228 0.018169 0.028684" quat="0.4717 0.512383 -0.624213 0.354007" mass="0.04069" diaginertia="1.37303e-05 1.07053e-05 9.12001e-06"/>
              <joint name="arm_joint5" pos="0 0 0" axis="0 0 1" range="-1.5708 3.14159"/>
              <geom type="mesh" contype="0" conaffinity="0" group="1" density="0" rgba="1 1 1 1" mesh="arm_link5"/>
              <geom type="mesh" rgba="1 1 1 1" mesh="arm_link5"/>
              <body name="rlink1" pos="-0.0035 -0.012625 -0.0685" quat="0.707105 0 -0.707108 0">
                <inertial pos="0.00653227 0.000416768 0.000980984" quat="0.0209119 0.706477 -0.0212978 0.707106" mass="0.00117883" diaginertia="1.99277e-07 1.67735e-07 3.25601e-08"/>
                <joint name="grip_joint" pos="0 0 0" axis="0 0 1" range="-1.54 0" damping="0.1"/>
                <geom type="mesh" contype="0" conaffinity="0" group="1" density="0" rgba="1 1 1 1" mesh="rlink1"/>
                <geom type="mesh" rgba="1 1 1 1" mesh="rlink1"/>
                <body name="rlink2" pos="0.03 -0.00075429 0">
                  <inertial pos="0.021158 0.0063295 -0.0030251" quat="-0.0773735 0.703432 0.064217 0.703614" mass="0.0024469" diaginertia="6.63645e-07 6.57049e-07 2.68654e-08"/>
                  <joint name="rlink_joint2" pos="0 0 0" axis="0 0 1" damping="0.1"/>
                  <geom type="mesh" contype="0" conaffinity="0" group="1" density="0" rgba="1 1 1 1" mesh="rlink2"/>
                  <geom type="mesh" rgba="1 1 1 1" mesh="rlink2"/>
                </body>
              </body>
            </body>
          </body>
        </body>
      </body>
    </body>
	</body>
  </worldbody>
  
  <contact>
	<exclude name="e1" body1="base_link" body2="arm_link1" />
  </contact>

  <!-- 这是有关关节之间特别是指末端执行器之间的约束关系 -->
  <equality>
  </equality>

  <!-- 这是有关执行器的定义 -->
  <actuator>
    <position name="arm_joint2" joint="arm_joint2" ctrllimited="true" ctrlrange="-0.875 0.875" forcelimited="true" forcerange="-100 100" />
    <position name="arm_joint3" joint="arm_joint3" ctrllimited="true" ctrlrange="-0.875 0.875" forcelimited="true" forcerange="-100 100" />
    <position name="arm_joint4" joint="arm_joint4" ctrllimited="true" ctrlrange="-0.875 0.875" forcelimited="true" forcerange="-100 100" />
    <position name="arm_joint5" joint="arm_joint5" ctrllimited="true" ctrlrange="-0.875 0.875" forcelimited="true" forcerange="-100 100" />
    <position name="grip_joint" joint="grip_joint" ctrllimited="true" ctrlrange="-0.875 0.875" forcelimited="true" forcerange="-100 100" />
	<position name="arm_joint1" joint="arm_joint1" ctrllimited="true" ctrlrange="-1.5708 1.5708" forcelimited="true" forcerange="-30 30" />
  </actuator>

</mujoco>
